<!-- Compatible with both Mujoco and Mujoco MJX. Replaces all cylinder geoms with spheres.
- Introduced mass on thigh, shank, wheel.
- Contacts turned off except feet. 
-->

<mujoco model="anymal_c">
  <compiler angle="radian" autolimits="true"/>
  <option timestep="0.002" iterations="5" ls_iterations="6" solver="Newton"/>
  <option cone="pyramidal"/>

  <visual>
    <headlight diffuse="0.6 0.6 0.6" ambient="0.3 0.3 0.3" specular="0 0 0"/>
    <rgba haze="0.15 0.25 0.35 1"/>
    <global azimuth="120" elevation="-20"/>
  </visual>

  <default>
    <default class="general">
      <joint damping="0.1"/>
      <geom priority="1" condim="3" friction="0.8 0.02 0.01" contype="8" conaffinity="4"/>
      <default class="collision">
        <geom/> 
      </default>
      <!-- main leg bodies  -->
      <!-- default pos and quats: no offset, no rotation. No self-collision. -->
      <default class="thigh">
        <geom priority="1" condim="3" friction="0.8 0.02 0.01" type="capsule" size="0.005" fromto="0 0 0 0.06 0 0" mass="0.03"/>
      </default>
      <default class="shank">
        <geom priority="1" condim="3" friction="0.8 0.02 0.01" type="capsule" size="0.005" fromto="0 0 0 0.06 0 0" mass="0.03"/>
      </default>
      <default class="wheel">
        <geom priority="1" condim="3" friction="0.8 0.02 0.01" size="0.015" type="sphere" contype="1" conaffinity="0" mass="0.03"/>
      </default>

      <!-- main leg joints  -->
      <default class="hip_joint">
        <joint axis="0 -1 0" range="-3.14 3.14"/>
      </default>
      <default class="knee_joint">
        <joint axis="0 -1 0" range="-3.14 3.14"/>
      </default>
      <default class="wheel_joint">
        <joint axis="0 -1 0"/>
      </default>

      <!-- motors -->
      <default class="servo_motor">
        <geom mass="0.05" type="sphere" size="0.015"/>
      </default>

      <!-- dc motor; assume point mass (to hide it) -->
      <default class="dc_motor">
        <geom mass="0.05" type="sphere" size="0.001"/>
      </default>

      <!-- motor actuation specs. -->
      <default class="position">
        <position kp="1" ctrlrange="-3.14 3.14" forcerange="-1 1"/>
      </default>
      <default class="affine">
        <motor gear="1" forcerange="-1 1" ctrlrange="-4 4"/>
      </default>

    </default>
  </default>

<!-- visual stuff -->
  <asset>
    <!-- Skybox makes the sky light blue rather than black. Groundplane makes an infinite ground area. -->
    <texture type="skybox" builtin="gradient" rgb1="0.3 0.5 0.7" rgb2="0 0 0" width="512" height="3072"/>
    <texture type="2d" name="groundplane" builtin="checker" mark="edge" rgb1="0.2 0.3 0.4" rgb2="0.1 0.2 0.3"
      markrgb="0.8 0.8 0.8" width="300" height="300"/>
    <material name="groundplane" texture="groundplane" texuniform="true" texrepeat="5 5" reflectance="0.2"/>
  </asset>

  <worldbody>
    <geom name="floor" size="0 0 0.05" type="plane" conaffinity="1" material="groundplane"/>
    <!-- This light uniformly lights the entire environment. -->
    <light pos="0 0 1.5" dir="0 0 -1" directional="true"/>

    <body name="base" pos="0 0 0.135" quat="1 0 0 0" childclass="general">
      <camera name="base" pos="0 -0.5 0.2" xyaxes="1 0 0 0 1 2" mode="targetbodycom"/>
      <freejoint/>
      <geom class="collision" pos="0 0 0" quat="1 0 0 0" type="box" size="0.07 0.04 0.0075" mass="0.2"/>

      <!-- Head; no inertial properties. No joint specified = fixed. -->
      <body name="head" pos="0.07 0 0">
        <geom class="collision" type="box" size="0.015 0.015 0.01"/>
      </body>

      <!-- HIP (massless; just a transform to make 0 degrees point vertically down.)-->
      <body name="RF_HIP" pos="0.07 0.04 0" quat="0.707107 0 0.707107 0">
        
        <!-- THIGH (attached to hip) -->
        <body pos="0 0 0">
          <joint name="RF_HJ" class="hip_joint"/>
          <geom class="servo_motor"/>
          <geom class="thigh"/>
          
          <!-- KNEE -->
          <body pos="0.06 0 0">
            <joint name="RF_KJ" class="knee_joint"/>
            <geom class="servo_motor"/>
            <geom class="shank"/>

            <!-- WHEEL (rotate so +'ve moves you forwards) -->
            <body pos="0.06 0 0" quat="0 1 0 0">
                <!-- <joint name="RF_WJ" class="wheel_joint"/> -->
                <geom class="dc_motor"/>
                <geom class="wheel"/>
            </body>
          </body>
        </body>
      </body>

      <!-- HIP -->
      <body name="LF_HIP" pos="0.07 -0.04 0" quat="0.707107 0 0.707107 0">
        
        <!-- THIGH -->
        <body pos="0 0 0">
          <joint class="hip_joint" name="LF_HJ"/>
          <geom class="servo_motor"/>
          <geom class="thigh"/>
          
          <!-- KNEE -->
          <body pos="0.06 0 0">
            <joint name="LF_KJ" class="knee_joint"/>
            <geom class="servo_motor"/>
            <geom class="shank"/>

            <!-- WHEEL -->
            <body pos="0.06 0 0" quat="0 1 0 0">
                <!-- <joint class="wheel_joint" name="LF_WJ"/> -->
                <geom class="dc_motor"/>
                <geom class="wheel"/>
            </body>
          </body>
        </body>
      </body>

      <!-- HIP -->
      <body name="RH_HIP" pos="-0.07 0.04 0" quat="0.707107 0 0.707107 0">
        
        <!-- THIGH -->
        <body pos="0 0 0">
          <joint class="hip_joint" name="RH_HJ"/>
          <geom class="servo_motor"/>
          <geom class="thigh"/>
          
          <!-- KNEE -->
          <body pos="0.06 0 0">
            <joint name="RH_KJ" class="knee_joint"/>
            <geom class="servo_motor"/>
            <geom class="shank"/>

            <!-- WHEEL -->
            <body pos="0.06 0 0" quat="0 1 0 0">
                <!-- <joint class="wheel_joint" name="RH_WJ"/> -->
                <geom class="dc_motor"/>
                <geom class="wheel"/>
            </body>
          </body>
        </body>
      </body>

      <!-- HIP -->
      <body name="LH_HIP" pos="-0.07 -0.04 0" quat="0.707107 0 0.707107 0">
        
        <!-- THIGH -->
        <body pos="0 0 0">
          <joint class="hip_joint" name="LH_HJ"/>
          <geom class="servo_motor"/>
          <geom class="thigh"/>
          
          <!-- KNEE -->
          <body pos="0.06 0 0">
            <joint name="LH_KJ" class="knee_joint"/>
            <geom class="servo_motor"/>
            <geom class="shank"/>

            <!-- WHEEL -->
            <body pos="0.06 0 0" quat="0 1 0 0">
                <!-- <joint class="wheel_joint" name="LH_WJ"/> -->
                <geom class="dc_motor"/>
                <geom class="wheel"/>
            </body>

          </body>
        </body>
      </body>

    </body>
  </worldbody>

  <actuator>
    <position class="position" joint="RF_HJ"/>
    <position class="position" joint="RF_KJ"/>
    <position class="position" joint="LF_HJ"/>
    <position class="position" joint="LF_KJ"/>
    <position class="position" joint="RH_HJ"/>
    <position class="position" joint="RH_KJ"/>
    <position class="position" joint="LH_HJ"/>
    <position class="position" joint="LH_KJ"/>
    
    <!-- <general class="affine" joint="RF_WJ"/>
    <general class="affine" joint="LF_WJ"/>
    <general class="affine" joint="RH_WJ"/>
    <general class="affine" joint="LH_WJ"/> -->
  </actuator>

  <keyframe> 
    <key name="standing" qpos="0.0 0.0 0.135 1.0 0.0 0.0 0.0 -0.7854 1.5708 -0.7854 1.5708 -0.7854 1.5708 -0.7854 1.5708" ctrl="-0.7854 1.5708 -0.7854 1.5708 -0.7854 1.5708 -0.7854 1.5708"/>
  </keyframe>

</mujoco>